<?xml version="1.0" ?>
<!-- =================================================================================== -->
<!-- |    This document was autogenerated by xacro from /home/haminmj/ws_moveit/src/rbmuse_description/urdf/rbmuse.xacro | -->
<!-- |    EDITING THIS FILE BY HAND IS NOT RECOMMENDED                                 | -->
<!-- =================================================================================== -->
<robot name="rbmuse">
    <material name="silver">
        <color rgba="0.700 0.700 0.700 1.000" />
    </material>
    <transmission name="Revolute 2_tran">
        <type>transmission_interface/SimpleTransmission</type>
        <joint name="Revolute 2">
            <hardwareInterface>hardware_interface/EffortJointInterface</hardwareInterface>
        </joint>
        <actuator name="Revolute 2_actr">
            <hardwareInterface>hardware_interface/EffortJointInterface</hardwareInterface>
            <mechanicalReduction>1</mechanicalReduction>
        </actuator>
    </transmission>
    <transmission name="Revolute 4_tran">
        <type>transmission_interface/SimpleTransmission</type>
        <joint name="Revolute 4">
            <hardwareInterface>hardware_interface/EffortJointInterface</hardwareInterface>
        </joint>
        <actuator name="Revolute 4_actr">
            <hardwareInterface>hardware_interface/EffortJointInterface</hardwareInterface>
            <mechanicalReduction>1</mechanicalReduction>
        </actuator>
    </transmission>
    <transmission name="Revolute 6_tran">
        <type>transmission_interface/SimpleTransmission</type>
        <joint name="Revolute 6">
            <hardwareInterface>hardware_interface/EffortJointInterface</hardwareInterface>
        </joint>
        <actuator name="Revolute 6_actr">
            <hardwareInterface>hardware_interface/EffortJointInterface</hardwareInterface>
            <mechanicalReduction>1</mechanicalReduction>
        </actuator>
    </transmission>
    <transmission name="Revolute 9_tran">
        <type>transmission_interface/SimpleTransmission</type>
        <joint name="Revolute 9">
            <hardwareInterface>hardware_interface/EffortJointInterface</hardwareInterface>
        </joint>
        <actuator name="Revolute 9_actr">
            <hardwareInterface>hardware_interface/EffortJointInterface</hardwareInterface>
            <mechanicalReduction>1</mechanicalReduction>
        </actuator>
    </transmission>
    <transmission name="Revolute 41_tran">
        <type>transmission_interface/SimpleTransmission</type>
        <joint name="Revolute 41">
            <hardwareInterface>hardware_interface/EffortJointInterface</hardwareInterface>
        </joint>
        <actuator name="Revolute 41_actr">
            <hardwareInterface>hardware_interface/EffortJointInterface</hardwareInterface>
            <mechanicalReduction>1</mechanicalReduction>
        </actuator>
    </transmission>
    <transmission name="Revolute 43_tran">
        <type>transmission_interface/SimpleTransmission</type>
        <joint name="Revolute 43">
            <hardwareInterface>hardware_interface/EffortJointInterface</hardwareInterface>
        </joint>
        <actuator name="Revolute 43_actr">
            <hardwareInterface>hardware_interface/EffortJointInterface</hardwareInterface>
            <mechanicalReduction>1</mechanicalReduction>
        </actuator>
    </transmission>
    <transmission name="Revolute 45_tran">
        <type>transmission_interface/SimpleTransmission</type>
        <joint name="Revolute 45">
            <hardwareInterface>hardware_interface/EffortJointInterface</hardwareInterface>
        </joint>
        <actuator name="Revolute 45_actr">
            <hardwareInterface>hardware_interface/EffortJointInterface</hardwareInterface>
            <mechanicalReduction>1</mechanicalReduction>
        </actuator>
    </transmission>
    <gazebo>
        <plugin filename="libgazebo_ros_control.so" name="control" />
        <plugin name="gazebo_ros_control">
            <robotNamespace>/</robotNamespace>
        </plugin>
    </gazebo>
    <gazebo reference="base_link">
        <material>Gazebo/Silver</material>
        <mu1>0.2</mu1>
        <mu2>0.2</mu2>
        <selfCollide>true</selfCollide>
        <gravity>true</gravity>
    </gazebo>
    <gazebo reference="motor1_1">
        <material>Gazebo/Silver</material>
        <mu1>0.2</mu1>
        <mu2>0.2</mu2>
        <selfCollide>true</selfCollide>
    </gazebo>
    <gazebo reference="disk_1">
        <material>Gazebo/Silver</material>
        <mu1>0.2</mu1>
        <mu2>0.2</mu2>
        <selfCollide>true</selfCollide>
    </gazebo>
    <gazebo reference="motor2_1">
        <material>Gazebo/Silver</material>
        <mu1>0.2</mu1>
        <mu2>0.2</mu2>
        <selfCollide>true</selfCollide>
    </gazebo>
    <gazebo reference="bigu_1">
        <material>Gazebo/Silver</material>
        <mu1>0.2</mu1>
        <mu2>0.2</mu2>
        <selfCollide>true</selfCollide>
    </gazebo>
    <gazebo reference="smallu_1">
        <material>Gazebo/Silver</material>
        <mu1>0.2</mu1>
        <mu2>0.2</mu2>
        <selfCollide>true</selfCollide>
    </gazebo>
    <gazebo reference="motor3_1">
        <material>Gazebo/Silver</material>
        <mu1>0.2</mu1>
        <mu2>0.2</mu2>
        <selfCollide>true</selfCollide>
    </gazebo>
    <gazebo reference="lshape_1">
        <material>Gazebo/Silver</material>
        <mu1>0.2</mu1>
        <mu2>0.2</mu2>
        <selfCollide>true</selfCollide>
    </gazebo>
    <gazebo reference="smallu1_1">
        <material>Gazebo/Silver</material>
        <mu1>0.2</mu1>
        <mu2>0.2</mu2>
        <selfCollide>true</selfCollide>
    </gazebo>
    <gazebo reference="motor4_1">
        <material>Gazebo/Silver</material>
        <mu1>0.2</mu1>
        <mu2>0.2</mu2>
        <selfCollide>true</selfCollide>
    </gazebo>
    <gazebo reference="lshape2_1">
        <material>Gazebo/Silver</material>
        <mu1>0.2</mu1>
        <mu2>0.2</mu2>
        <selfCollide>true</selfCollide>
    </gazebo>
    <gazebo reference="motor5_1">
        <material>Gazebo/Silver</material>
        <mu1>0.2</mu1>
        <mu2>0.2</mu2>
        <selfCollide>true</selfCollide>
    </gazebo>
    <gazebo reference="gbase_1">
        <material>Gazebo/Silver</material>
        <mu1>0.2</mu1>
        <mu2>0.2</mu2>
        <selfCollide>true</selfCollide>
    </gazebo>
    <gazebo reference="motor6_1">
        <material>Gazebo/Silver</material>
        <mu1>0.2</mu1>
        <mu2>0.2</mu2>
        <selfCollide>true</selfCollide>
    </gazebo>
    <gazebo reference="glinkr_1">
        <material>Gazebo/Silver</material>
        <mu1>0.2</mu1>
        <mu2>0.2</mu2>
        <selfCollide>true</selfCollide>
    </gazebo>
    <gazebo reference="clawr_1">
        <material>Gazebo/Silver</material>
        <mu1>0.2</mu1>
        <mu2>0.2</mu2>
        <selfCollide>true</selfCollide>
    </gazebo>
    <gazebo reference="glinkl_1">
        <material>Gazebo/Silver</material>
        <mu1>0.2</mu1>
        <mu2>0.2</mu2>
        <selfCollide>true</selfCollide>
    </gazebo>
    <gazebo reference="clawl_1">
        <material>Gazebo/Silver</material>
        <mu1>0.2</mu1>
        <mu2>0.2</mu2>
        <selfCollide>true</selfCollide>
    </gazebo>
    <link name="base_link">
        <inertial>
            <origin rpy="0 0 0" xyz="-0.026168976468017534 -0.0005496586417581346 0.01778804529166589" />
            <mass value="3.0751047880633586" />
            <inertia ixx="0.002856" ixy="7e-06" ixz="0.000585" iyy="0.006289" iyz="-1e-06" izz="0.007631" />
        </inertial>
        <visual>
            <origin rpy="0 0 0" xyz="0 0 0" />
            <geometry>
                <mesh filename="package://rbmuse_description/meshes/base_link.stl" scale="0.001 0.001 0.001" />
            </geometry>
            <material name="silver" />
        </visual>
        <collision>
            <origin rpy="0 0 0" xyz="0 0 0" />
            <geometry>
                <mesh filename="package://rbmuse_description/meshes/base_link.stl" scale="0.001 0.001 0.001" />
            </geometry>
        </collision>
    </link>
    <link name="motor1_1">
        <inertial>
            <origin rpy="0 0 0" xyz="0.03930371256985485 0.0021696453874637547 -0.008593146614866543" />
            <mass value="0.24771286336269865" />
            <inertia ixx="6.4e-05" ixy="-0.0" ixz="-0.0" iyy="3.8e-05" iyz="-1e-06" izz="4.3e-05" />
        </inertial>
        <visual>
            <origin rpy="0 0 0" xyz="0.079145 0.00249 -0.050267" />
            <geometry>
                <mesh filename="package://rbmuse_description/meshes/motor1_1.stl" scale="0.001 0.001 0.001" />
            </geometry>
            <material name="silver" />
        </visual>
        <collision>
            <origin rpy="0 0 0" xyz="0.079145 0.00249 -0.050267" />
            <geometry>
                <mesh filename="package://rbmuse_description/meshes/motor1_1.stl" scale="0.001 0.001 0.001" />
            </geometry>
        </collision>
    </link>
    <link name="disk_1">
        <inertial>
            <origin rpy="0 0 0" xyz="3.492033330554367e-07 9.747354081292986e-07 0.005492676065882121" />
            <mass value="0.5311101141935193" />
            <inertia ixx="0.000261" ixy="0.0" ixz="0.0" iyy="0.000261" iyz="0.0" izz="0.000509" />
        </inertial>
        <visual>
            <origin rpy="0 0 0" xyz="0.039762 -0.009587 -0.06413" />
            <geometry>
                <mesh filename="package://rbmuse_description/meshes/disk_1.stl" scale="0.001 0.001 0.001" />
            </geometry>
            <material name="silver" />
        </visual>
        <collision>
            <origin rpy="0 0 0" xyz="0.039762 -0.009587 -0.06413" />
            <geometry>
                <mesh filename="package://rbmuse_description/meshes/disk_1.stl" scale="0.001 0.001 0.001" />
            </geometry>
        </collision>
    </link>
    <link name="motor2_1">
        <inertial>
            <origin rpy="0 0 0" xyz="0.0005432628975196307 0.00019610580267081373 0.0102500382122543" />
            <mass value="0.24771286336269865" />
            <inertia ixx="4.3e-05" ixy="-1e-06" ixz="0.0" iyy="3.8e-05" iyz="0.0" izz="6.4e-05" />
        </inertial>
        <visual>
            <origin rpy="0 0 0" xyz="0.039761 -0.00959 -0.08013" />
            <geometry>
                <mesh filename="package://rbmuse_description/meshes/motor2_1.stl" scale="0.001 0.001 0.001" />
            </geometry>
            <material name="silver" />
        </visual>
        <collision>
            <origin rpy="0 0 0" xyz="0.039761 -0.00959 -0.08013" />
            <geometry>
                <mesh filename="package://rbmuse_description/meshes/motor2_1.stl" scale="0.001 0.001 0.001" />
            </geometry>
        </collision>
    </link>
    <link name="bigu_1">
        <inertial>
            <origin rpy="0 0 0" xyz="-0.02199563550171054 0.0001809953785818011 0.028905156107693994" />
            <mass value="0.0784222615280103" />
            <inertia ixx="3.4e-05" ixy="0.0" ixz="2e-06" iyy="7.5e-05" iyz="-0.0" izz="5e-05" />
        </inertial>
        <visual>
            <origin rpy="0 0 0" xyz="0.016681 -0.01951 -0.090377" />
            <geometry>
                <mesh filename="package://rbmuse_description/meshes/bigu_1.stl" scale="0.001 0.001 0.001" />
            </geometry>
            <material name="silver" />
        </visual>
        <collision>
            <origin rpy="0 0 0" xyz="0.016681 -0.01951 -0.090377" />
            <geometry>
                <mesh filename="package://rbmuse_description/meshes/bigu_1.stl" scale="0.001 0.001 0.001" />
            </geometry>
        </collision>
    </link>
    <link name="smallu_1">
        <inertial>
            <origin rpy="0 0 0" xyz="9.380930374724983e-07 2.4460137672752125e-06 0.011594145388475141" />
            <mass value="0.05393922534960198" />
            <inertia ixx="1.2e-05" ixy="0.0" ixz="0.0" iyy="3.7e-05" iyz="-0.0" izz="3e-05" />
        </inertial>
        <visual>
            <origin rpy="0 0 0" xyz="0.041679 -0.01972 -0.141378" />
            <geometry>
                <mesh filename="package://rbmuse_description/meshes/smallu_1.stl" scale="0.001 0.001 0.001" />
            </geometry>
            <material name="silver" />
        </visual>
        <collision>
            <origin rpy="0 0 0" xyz="0.041679 -0.01972 -0.141378" />
            <geometry>
                <mesh filename="package://rbmuse_description/meshes/smallu_1.stl" scale="0.001 0.001 0.001" />
            </geometry>
        </collision>
    </link>
    <link name="motor3_1">
        <inertial>
            <origin rpy="0 0 0" xyz="-0.024457366779002194 0.00019600493077282302 0.009903111346328625" />
            <mass value="0.24771286336269865" />
            <inertia ixx="4.3e-05" ixy="0.0" ixz="1e-06" iyy="6.4e-05" iyz="-0.0" izz="3.8e-05" />
        </inertial>
        <visual>
            <origin rpy="0 0 0" xyz="0.015678 -0.019521 -0.172877" />
            <geometry>
                <mesh filename="package://rbmuse_description/meshes/motor3_1.stl" scale="0.001 0.001 0.001" />
            </geometry>
            <material name="silver" />
        </visual>
        <collision>
            <origin rpy="0 0 0" xyz="0.015678 -0.019521 -0.172877" />
            <geometry>
                <mesh filename="package://rbmuse_description/meshes/motor3_1.stl" scale="0.001 0.001 0.001" />
            </geometry>
        </collision>
    </link>
    <link name="lshape_1">
        <inertial>
            <origin rpy="0 0 0" xyz="-0.1647141046884117 -0.051643015147499916 0.036814200251928664" />
            <mass value="0.03417797904336539" />
            <inertia ixx="7e-06" ixy="-0.0" ixz="-0.0" iyy="5e-06" iyz="-2e-06" izz="7e-06" />
        </inertial>
        <visual>
            <origin rpy="0 0 0" xyz="-0.124023 -0.069424 -0.173711" />
            <geometry>
                <mesh filename="package://rbmuse_description/meshes/lshape_1.stl" scale="0.001 0.001 0.001" />
            </geometry>
            <material name="silver" />
        </visual>
        <collision>
            <origin rpy="0 0 0" xyz="-0.124023 -0.069424 -0.173711" />
            <geometry>
                <mesh filename="package://rbmuse_description/meshes/lshape_1.stl" scale="0.001 0.001 0.001" />
            </geometry>
        </collision>
    </link>
    <link name="smallu1_1">
        <inertial>
            <origin rpy="0 0 0" xyz="6.186610709002505e-07 2.474644159582151e-06 0.011593815204141433" />
            <mass value="0.05393922534960198" />
            <inertia ixx="1.2e-05" ixy="0.0" ixz="0.0" iyy="3.7e-05" iyz="-0.0" izz="3e-05" />
        </inertial>
        <visual>
            <origin rpy="0 0 0" xyz="0.040561 -0.034179 -0.217975" />
            <geometry>
                <mesh filename="package://rbmuse_description/meshes/smallu1_1.stl" scale="0.001 0.001 0.001" />
            </geometry>
            <material name="silver" />
        </visual>
        <collision>
            <origin rpy="0 0 0" xyz="0.040561 -0.034179 -0.217975" />
            <geometry>
                <mesh filename="package://rbmuse_description/meshes/smallu1_1.stl" scale="0.001 0.001 0.001" />
            </geometry>
        </collision>
    </link>
    <link name="motor4_1">
        <inertial>
            <origin rpy="0 0 0" xyz="-0.024379636684416315 0.010095761121906667 -1.7608738211438713e-06" />
            <mass value="0.24771286336269865" />
            <inertia ixx="4.3e-05" ixy="1e-06" ixz="0.0" iyy="3.8e-05" iyz="0.0" izz="6.4e-05" />
        </inertial>
        <visual>
            <origin rpy="0 0 0" xyz="0.01456 -0.03398 -0.249474" />
            <geometry>
                <mesh filename="package://rbmuse_description/meshes/motor4_1.stl" scale="0.001 0.001 0.001" />
            </geometry>
            <material name="silver" />
        </visual>
        <collision>
            <origin rpy="0 0 0" xyz="0.01456 -0.03398 -0.249474" />
            <geometry>
                <mesh filename="package://rbmuse_description/meshes/motor4_1.stl" scale="0.001 0.001 0.001" />
            </geometry>
        </collision>
    </link>
    <link name="lshape2_1">
        <inertial>
            <origin rpy="0 0 0" xyz="-0.24047463918656625 0.07237662687230707 0.06742629492159574" />
            <mass value="0.03417797904336539" />
            <inertia ixx="7e-06" ixy="-0.0" ixz="-0.0" iyy="5e-06" iyz="-2e-06" izz="7e-06" />
        </inertial>
        <visual>
            <origin rpy="0 0 0" xyz="-0.201205 0.001699 -0.199743" />
            <geometry>
                <mesh filename="package://rbmuse_description/meshes/lshape2_1.stl" scale="0.001 0.001 0.001" />
            </geometry>
            <material name="silver" />
        </visual>
        <collision>
            <origin rpy="0 0 0" xyz="-0.201205 0.001699 -0.199743" />
            <geometry>
                <mesh filename="package://rbmuse_description/meshes/lshape2_1.stl" scale="0.001 0.001 0.001" />
            </geometry>
        </collision>
    </link>
    <link name="motor5_1">
        <inertial>
            <origin rpy="0 0 0" xyz="0.08165331636898154 0.2981306692560505 0.059107909660422175" />
            <mass value="0.24771286336269865" />
            <inertia ixx="3.8e-05" ixy="1e-06" ixz="0.0" iyy="4.3e-05" iyz="0.0" izz="6.4e-05" />
        </inertial>
        <visual>
            <origin rpy="0 0 0" xyz="0.11088 0.197184 -0.220601" />
            <geometry>
                <mesh filename="package://rbmuse_description/meshes/motor5_1.stl" scale="0.001 0.001 0.001" />
            </geometry>
            <material name="silver" />
        </visual>
        <collision>
            <origin rpy="0 0 0" xyz="0.11088 0.197184 -0.220601" />
            <geometry>
                <mesh filename="package://rbmuse_description/meshes/motor5_1.stl" scale="0.001 0.001 0.001" />
            </geometry>
        </collision>
    </link>
    <link name="gbase_1">
        <inertial>
            <origin rpy="0 0 0" xyz="-0.0008440157289839254 0.030131425640598536 -7.070589467750299e-06" />
            <mass value="0.03250334179699039" />
            <inertia ixx="1.1e-05" ixy="0.0" ixz="0.0" iyy="5e-06" iyz="0.0" izz="1.5e-05" />
        </inertial>
        <visual>
            <origin rpy="0 0 0" xyz="0.038935 -0.125483 -0.279704" />
            <geometry>
                <mesh filename="package://rbmuse_description/meshes/gbase_1.stl" scale="0.001 0.001 0.001" />
            </geometry>
            <material name="silver" />
        </visual>
        <collision>
            <origin rpy="0 0 0" xyz="0.038935 -0.125483 -0.279704" />
            <geometry>
                <mesh filename="package://rbmuse_description/meshes/gbase_1.stl" scale="0.001 0.001 0.001" />
            </geometry>
        </collision>
    </link>
    <link name="motor6_1">
        <inertial>
            <origin rpy="0 0 0" xyz="0.04631958605241957 -0.288594688666587 0.12592984428841508" />
            <mass value="0.24771286336269865" />
            <inertia ixx="3.8e-05" ixy="0.0" ixz="1e-06" iyy="6.4e-05" iyz="-0.0" izz="4.3e-05" />
        </inertial>
        <visual>
            <origin rpy="0 0 0" xyz="0.061616 -0.437836 -0.131809" />
            <geometry>
                <mesh filename="package://rbmuse_description/meshes/motor6_1.stl" scale="0.001 0.001 0.001" />
            </geometry>
            <material name="silver" />
        </visual>
        <collision>
            <origin rpy="0 0 0" xyz="0.061616 -0.437836 -0.131809" />
            <geometry>
                <mesh filename="package://rbmuse_description/meshes/motor6_1.stl" scale="0.001 0.001 0.001" />
            </geometry>
        </collision>
    </link>
    <link name="glinkr_1">
        <inertial>
            <origin rpy="0 0 0" xyz="4.3168479621557426e-05 0.005489355444972671 0.0014984981238657658" />
            <mass value="0.01630298468358439" />
            <inertia ixx="2e-06" ixy="-0.0" ixz="0.0" iyy="1e-06" iyz="0.0" izz="3e-06" />
        </inertial>
        <visual>
            <origin rpy="0 0 0" xyz="0.025197 -0.149325 -0.282198" />
            <geometry>
                <mesh filename="package://rbmuse_description/meshes/glinkr_1.stl" scale="0.001 0.001 0.001" />
            </geometry>
            <material name="silver" />
        </visual>
        <collision>
            <origin rpy="0 0 0" xyz="0.025197 -0.149325 -0.282198" />
            <geometry>
                <mesh filename="package://rbmuse_description/meshes/glinkr_1.stl" scale="0.001 0.001 0.001" />
            </geometry>
        </collision>
    </link>
    <link name="clawr_1">
        <inertial>
            <origin rpy="0 0 0" xyz="-0.0047623050914065435 0.024422750111204483 0.0014943425639101782" />
            <mass value="0.012557670523597225" />
            <inertia ixx="4e-06" ixy="0.0" ixz="-0.0" iyy="0.0" iyz="0.0" izz="4e-06" />
        </inertial>
        <visual>
            <origin rpy="0 0 0" xyz="0.024952 -0.180325 -0.285191" />
            <geometry>
                <mesh filename="package://rbmuse_description/meshes/clawr_1.stl" scale="0.001 0.001 0.001" />
            </geometry>
            <material name="silver" />
        </visual>
        <collision>
            <origin rpy="0 0 0" xyz="0.024952 -0.180325 -0.285191" />
            <geometry>
                <mesh filename="package://rbmuse_description/meshes/clawr_1.stl" scale="0.001 0.001 0.001" />
            </geometry>
        </collision>
    </link>
    <link name="glinkl_1">
        <inertial>
            <origin rpy="0 0 0" xyz="0.0004973925200013815 0.005155127642888696 0.001498638427966159" />
            <mass value="0.01672496232433782" />
            <inertia ixx="2e-06" ixy="0.0" ixz="0.0" iyy="1e-06" iyz="0.0" izz="3e-06" />
        </inertial>
        <visual>
            <origin rpy="0 0 0" xyz="0.052197 -0.149539 -0.281199" />
            <geometry>
                <mesh filename="package://rbmuse_description/meshes/glinkl_1.stl" scale="0.001 0.001 0.001" />
            </geometry>
            <material name="silver" />
        </visual>
        <collision>
            <origin rpy="0 0 0" xyz="0.052197 -0.149539 -0.281199" />
            <geometry>
                <mesh filename="package://rbmuse_description/meshes/glinkl_1.stl" scale="0.001 0.001 0.001" />
            </geometry>
        </collision>
    </link>
    <link name="clawl_1">
        <inertial>
            <origin rpy="0 0 0" xyz="0.0036533334329303183 0.02461343385388537 0.0014940341220606168" />
            <mass value="0.012557670523597225" />
            <inertia ixx="4e-06" ixy="-0.0" ixz="0.0" iyy="0.0" iyz="0.0" izz="4e-06" />
        </inertial>
        <visual>
            <origin rpy="0 0 0" xyz="0.051996 -0.180528 -0.284192" />
            <geometry>
                <mesh filename="package://rbmuse_description/meshes/clawl_1.stl" scale="0.001 0.001 0.001" />
            </geometry>
            <material name="silver" />
        </visual>
        <collision>
            <origin rpy="0 0 0" xyz="0.051996 -0.180528 -0.284192" />
            <geometry>
                <mesh filename="package://rbmuse_description/meshes/clawl_1.stl" scale="0.001 0.001 0.001" />
            </geometry>
        </collision>
    </link>
    <joint name="Rigid1" type="fixed">
        <origin rpy="0 0 0" xyz="-0.079145 -0.00249 0.050267" />
        <parent link="base_link" />
        <child link="motor1_1" />
    </joint>
    <joint name="Revolute2" type="revolute">
        <origin rpy="0 0 0" xyz="0.039383 0.012077 0.013863" />
        <parent link="motor1_1" />
        <child link="disk_1" />
        <axis xyz="4.2e-05 0.000227 1.0" />
        <limit effort="100" lower="0.0" upper="3.141593" velocity="100" />
    </joint>
    <joint name="Rigid3" type="fixed">
        <origin rpy="0 0 0" xyz="1e-06 3e-06 0.016" />
        <parent link="disk_1" />
        <child link="motor2_1" />
    </joint>
    <joint name="Revolute4" type="revolute">
        <origin rpy="0 0 0" xyz="0.02308 0.00992 0.010247" />
        <parent link="motor2_1" />
        <child link="bigu_1" />
        <axis xyz="0.999969 -0.007924 -4e-05" />
        <limit effort="100" lower="-1.396263" upper="0.0" velocity="100" />
    </joint>
    <joint name="Rigid5" type="fixed">
        <origin rpy="0 0 0" xyz="-0.024998 0.00021 0.051001" />
        <parent link="bigu_1" />
        <child link="smallu_1" />
    </joint>
    <joint name="Revolute6" type="revolute">
        <origin rpy="0 0 0" xyz="0.026001 -0.000199 0.031499" />
        <parent link="smallu_1" />
        <child link="motor3_1" />
        <axis xyz="0.999969 -0.007924 -4e-05" />
        <limit effort="100" lower="0.0" upper="1.396263" velocity="100" />
    </joint>
    <joint name="Rigid7" type="fixed">
        <origin rpy="0 0 0" xyz="0.139701 0.049903 0.000834" />
        <parent link="motor3_1" />
        <child link="lshape_1" />
    </joint>
    <joint name="Rigid8" type="fixed">
        <origin rpy="0 0 0" xyz="-0.164584 -0.035245 0.044264" />
        <parent link="lshape_1" />
        <child link="smallu1_1" />
    </joint>
    <joint name="Revolute9" type="revolute">
        <origin rpy="0 0 0" xyz="0.026001 -0.000199 0.031499" />
        <parent link="smallu1_1" />
        <child link="motor4_1" />
        <axis xyz="0.999969 -0.007924 -4e-05" />
        <limit effort="100" lower="-0.349066" upper="0.0" velocity="100" />
    </joint>
    <joint name="Rigid39" type="fixed">
        <origin rpy="0 0 0" xyz="0.215765 -0.035679 -0.049731" />
        <parent link="motor4_1" />
        <child link="lshape2_1" />
    </joint>
    <joint name="Rigid40" type="fixed">
        <origin rpy="0 0 0" xyz="-0.312085 -0.195485 0.020858" />
        <parent link="lshape2_1" />
        <child link="motor5_1" />
    </joint>
    <joint name="Revolute41" type="revolute">
        <origin rpy="0 0 0" xyz="0.071945 0.322667 0.059103" />
        <parent link="motor5_1" />
        <child link="gbase_1" />
        <axis xyz="0.007924 0.999969 -0.000228" />
        <limit effort="100" lower="-0.349066" upper="0.0" velocity="100" />
    </joint>
    <joint name="Rigid42" type="fixed">
        <origin rpy="0 0 0" xyz="-0.022681 0.312353 -0.147895" />
        <parent link="gbase_1" />
        <child link="motor6_1" />
    </joint>
    <joint name="Revolute43" type="revolute">
        <origin rpy="0 0 0" xyz="0.036419 -0.288511 0.150389" />
        <parent link="motor6_1" />
        <child link="glinkr_1" />
        <axis xyz="4.2e-05 0.000227 1.0" />
        <limit effort="100" lower="-1.047198" upper="0.0" velocity="100" />
    </joint>
    <joint name="Rigid44" type="fixed">
        <origin rpy="0 0 0" xyz="0.000245 0.031 0.002993" />
        <parent link="glinkr_1" />
        <child link="clawr_1" />
    </joint>
    <joint name="Revolute45" type="revolute">
        <origin rpy="0 0 0" xyz="-0.013262 0.024056 0.001495" />
        <parent link="gbase_1" />
        <child link="glinkl_1" />
        <axis xyz="4.2e-05 0.000227 1.0" />
        <limit effort="100" lower="0.0" upper="-1.047198" velocity="100" />
        <mimic joint="Revolute43" multiplier="-1" offset="0" />
    </joint>
    <joint name="Rigid46" type="fixed">
        <origin rpy="0 0 0" xyz="0.000201 0.030989 0.002993" />
        <parent link="glinkl_1" />
        <child link="clawl_1" />
    </joint>
    <transmission name="trans_Revolute2">
        <type>transmission_interface/SimpleTransmission</type>
        <joint name="Revolute2">
            <hardwareInterface>hardware_interface/EffortJointInterface</hardwareInterface>
        </joint>
        <actuator name="Revolute2_motor">
            <hardwareInterface>hardware_interface/EffortJointInterface</hardwareInterface>
            <mechanicalReduction>1</mechanicalReduction>
        </actuator>
    </transmission>
    <transmission name="trans_Revolute4">
        <type>transmission_interface/SimpleTransmission</type>
        <joint name="Revolute4">
            <hardwareInterface>hardware_interface/EffortJointInterface</hardwareInterface>
        </joint>
        <actuator name="Revolute4_motor">
            <hardwareInterface>hardware_interface/EffortJointInterface</hardwareInterface>
            <mechanicalReduction>1</mechanicalReduction>
        </actuator>
    </transmission>
    <transmission name="trans_Revolute6">
        <type>transmission_interface/SimpleTransmission</type>
        <joint name="Revolute6">
            <hardwareInterface>hardware_interface/EffortJointInterface</hardwareInterface>
        </joint>
        <actuator name="Revolute6_motor">
            <hardwareInterface>hardware_interface/EffortJointInterface</hardwareInterface>
            <mechanicalReduction>1</mechanicalReduction>
        </actuator>
    </transmission>
    <transmission name="trans_Revolute9">
        <type>transmission_interface/SimpleTransmission</type>
        <joint name="Revolute9">
            <hardwareInterface>hardware_interface/EffortJointInterface</hardwareInterface>
        </joint>
        <actuator name="Revolute9_motor">
            <hardwareInterface>hardware_interface/EffortJointInterface</hardwareInterface>
            <mechanicalReduction>1</mechanicalReduction>
        </actuator>
    </transmission>
    <transmission name="trans_Revolute41">
        <type>transmission_interface/SimpleTransmission</type>
        <joint name="Revolute41">
            <hardwareInterface>hardware_interface/EffortJointInterface</hardwareInterface>
        </joint>
        <actuator name="Revolute41_motor">
            <hardwareInterface>hardware_interface/EffortJointInterface</hardwareInterface>
            <mechanicalReduction>1</mechanicalReduction>
        </actuator>
    </transmission>
    <transmission name="trans_Revolute43">
        <type>transmission_interface/SimpleTransmission</type>
        <joint name="Revolute43">
            <hardwareInterface>hardware_interface/EffortJointInterface</hardwareInterface>
        </joint>
        <actuator name="Revolute43_motor">
            <hardwareInterface>hardware_interface/EffortJointInterface</hardwareInterface>
            <mechanicalReduction>1</mechanicalReduction>
        </actuator>
    </transmission>
    <transmission name="trans_Revolute45">
        <type>transmission_interface/SimpleTransmission</type>
        <joint name="Revolute45">
            <hardwareInterface>hardware_interface/EffortJointInterface</hardwareInterface>
        </joint>
        <actuator name="Revolute45_motor">
            <hardwareInterface>hardware_interface/EffortJointInterface</hardwareInterface>
            <mechanicalReduction>1</mechanicalReduction>
        </actuator>
    </transmission>
</robot>

